Workbook
Name Slicer_Customer_Type: #N/A
Name Slicer_Drug_Name: #N/A
Name Slicer_Quarter: #N/A
Name Slicer_Region: #N/A

Sheet Raw_Data 
A1: Drug Name | B1: Manufacturer | C1: Dosage Form | D1: Strength | E1: Package Size | F1: Units Sold | G1: Revenue | H1: Sale Date | I1: Region | J1: Sales Representative | K1: Customer Type
A2: Drug B | B2: Company W | C2: Tablet | D2: 100 mg/ml | E2: 50 g | F2: 1500 | G2: 43833 | H2: 45329 | I2: South America | J2: Susan Hernandez | K2: Clinics
A3: Drug B | B3: Company X | C3: Cream | D3: 500 mg | E3: 100 ml | F3: 1194 | G3: 48717 | H3: 45146 | I3: South America | J3: Jackie Wagner | K3: Clinics
A4: Drug E | B4: Company X | C4: Capsule | D4: 50 mg | E4: 60 | F4: 618 | G4: 8744 | H4: 45458 | I4: Africa | J4: Mariah Mccoy | K4: Hospitals
A5: Drug E | B5: Company X | C5: Injection | D5: 10 mg | E5: 100 ml | F5: 1455 | G5: 25321 | H5: 45488 | I5: Asia | J5: Courtney Doyle | K5: Pharmacy
A6: Drug C | B6: Company V | C6: Tablet | D6: 100 mg/ml | E6: 50 g | F6: 130 | G6: 13669 | H6: 45151 | I6: South America | J6: Dawn Torres | K6: Clinics
A7: Drug B | B7: Company V | C7: Capsule | D7: 100 mg/ml | E7: 10 ml | F7: 619 | G7: 7552 | H7: 45265 | I7: Europe | J7: Jessica Faulkner | K7: Hospitals
A8: Drug C | B8: Company X | C8: Cream | D8: 500 mg | E8: 30 | F8: 1779 | G8: 48563 | H8: 45146 | I8: North America | J8: Alicia Howard | K8: Hospitals
A9: Drug B | B9: Company X | C9: Tablet | D9: 500 mg | E9: 10 ml | F9: 1727 | G9: 13672 | H9: 45290 | I9: Asia | J9: David Hill | K9: Online Pharmacy
A10: Drug A | B10: Company V | C10: Capsule | D10: 500 mg | E10: 50 g | F10: 451 | G10: 45835 | H10: 45244 | I10: Asia | J10: Matthew Johnson | K10: Supermarkets
A11: Drug C | B11: Company X | C11: Cream | D11: 10 mg | E11: 10 ml | F11: 1006 | G11: 31716 | H11: 45435 | I11: Asia | J11: Kimberly Murphy | K11: Supermarkets
A12: Drug C | B12: Company Y | C12: Capsule | D12: 50 mg | E12: 100 ml | F12: 1633 | G12: 33931 | H12: 45430 | I12: Europe | J12: Tyler Brown | K12: Pharmacy
A13: Drug A | B13: Company Z | C13: Cream | D13: 50 mg | E13: 30 | F13: 128 | G13: 35258 | H13: 45238 | I13: North America | J13: Sheila Coleman | K13: Online Pharmacy
A14: Drug C | B14: Company V | C14: Injection | D14: 500 mg | E14: 10 ml | F14: 504 | G14: 36459 | H14: 45157 | I14: Europe | J14: Douglas Rodriguez | K14: Pharmacy
A15: Drug E | B15: Company V | C15: Cream | D15: 500 mg | E15: 100 ml | F15: 216 | G15: 32152 | H15: 45481 | I15: Europe | J15: Brandi King | K15: Pharmacy
A16: Drug E | B16: Company V | C16: Injection | D16: 10 mg | E16: 10 ml | F16: 1986 | G16: 13538 | H16: 45263 | I16: Europe | J16: Susan Brewer | K16: Pharmacy
A17: Drug A | B17: Company W | C17: Cream | D17: 50 mg | E17: 30 | F17: 1977 | G17: 9566 | H17: 45486 | I17: Africa | J17: Latoya Wright | K17: Online Pharmacy
A18: Drug A | B18: Company V | C18: Tablet | D18: 100 mg/ml | E18: 50 g | F18: 1320 | G18: 29932 | H18: 45160 | I18: North America | J18: Richard Edwards | K18: Clinics
A19: Drug E | B19: Company W | C19: Cream | D19: 10 mg | E19: 30 | F19: 1766 | G19: 45608 | H19: 45349 | I19: South America | J19: Mr. Michael Taylor | K19: Pharmacy
A20: Drug B | B20: Company X | C20: Syrup | D20: 100 mg/ml | E20: 60 | F20: 1078 | G20: 42394 | H20: 45303 | I20: South America | J20: Angela Castro | K20: Online Pharmacy
A21: Drug C | B21: Company X | C21: Injection | D21: 500 mg | E21: 60 | F21: 783 | G21: 48016 | H21: 45315 | I21: Asia | J21: Christie Brown | K21: Clinics
A22: Drug E | B22: Company X | C22: Capsule | D22: 100 mg/ml | E22: 60 | F22: 1161 | G22: 11048 | H22: 45299 | I22: Europe | J22: Annette Fisher | K22: Clinics
A23: Drug A | B23: Company X | C23: Capsule | D23: 50 mg | E23: 50 g | F23: 1820 | G23: 16952 | H23: 45366 | I23: Africa | J23: Katelyn Smith | K23: Hospitals
A24: Drug D | B24: Company V | C24: Tablet | D24: 50 mg | E24: 60 | F24: 147 | G24: 28543 | H24: 45437 | I24: Africa | J24: Crystal Lawrence | K24: Hospitals
A25: Drug B | B25: Company Z | C25: Capsule | D25: 250 mg | E25: 60 | F25: 990 | G25: 5766 | H25: 45172 | I25: North America | J25: Katherine Sexton | K25: Online Pharmacy
A26: Drug B | B26: Company Z | C26: Injection | D26: 500 mg | E26: 60 | F26: 223 | G26: 23153 | H26: 45371 | I26: Asia | J26: Felicia Jones | K26: Online Pharmacy
A27: Drug D | B27: Company Z | C27: Syrup | D27: 250 mg | E27: 50 g | F27: 855 | G27: 22920 | H27: 45313 | I27: South America | J27: Lisa Johnson | K27: Supermarkets
A28: Drug C | B28: Company X | C28: Cream | D28: 50 mg | E28: 100 ml | F28: 968 | G28: 6595 | H28: 45264 | I28: Africa | J28: Amber Hill | K28: Hospitals
A29: Drug B | B29: Company W | C29: Cream | D29: 10 mg | E29: 10 ml | F29: 1378 | G29: 37523 | H29: 45271 | I29: South America | J29: Rebecca Lawrence | K29: Online Pharmacy
A30: Drug B | B30: Company Z | C30: Tablet | D30: 500 mg | E30: 100 ml | F30: 1473 | G30: 23815 | H30: 45495 | I30: South America | J30: John Smith | K30: Supermarkets
A31: Drug C | B31: Company X | C31: Capsule | D31: 250 mg | E31: 100 ml | F31: 791 | G31: 40754 | H31: 45417 | I31: Africa | J31: Scott Jones | K31: Hospitals
A32: Drug C | B32: Company V | C32: Tablet | D32: 10 mg | E32: 50 g | F32: 1523 | G32: 35645 | H32: 45211 | I32: South America | J32: Cynthia Cook | K32: Clinics
A33: Drug E | B33: Company W | C33: Cream | D33: 250 mg | E33: 50 g | F33: 1214 | G33: 1820 | H33: 45359 | I33: South America | J33: Randy Dunn | K33: Online Pharmacy
A34: Drug C | B34: Company V | C34: Injection | D34: 250 mg | E34: 60 | F34: 440 | G34: 13578 | H34: 45470 | I34: Asia | J34: Michael Cisneros | K34: Hospitals
A35: Drug D | B35: Company Y | C35: Syrup | D35: 10 mg | E35: 60 | F35: 1574 | G35: 47682 | H35: 45396 | I35: Africa | J35: Crystal Keller | K35: Supermarkets
A36: Drug A | B36: Company W | C36: Cream | D36: 250 mg | E36: 50 g | F36: 1880 | G36: 41604 | H36: 45295 | I36: North America | J36: Christina Lopez | K36: Pharmacy
A37: Drug E | B37: Company Z | C37: Tablet | D37: 100 mg/ml | E37: 10 ml | F37: 383 | G37: 21024 | H37: 45298 | I37: South America | J37: Christopher Taylor | K37: Hospitals
A38: Drug E | B38: Company Y | C38: Injection | D38: 10 mg | E38: 10 ml | F38: 253 | G38: 18363 | H38: 45459 | I38: South America | J38: Lisa Alvarado | K38: Online Pharmacy
A39: Drug C | B39: Company Y | C39: Syrup | D39: 100 mg/ml | E39: 30 | F39: 1818 | G39: 2347 | H39: 45320 | I39: Africa | J39: Kerry Oneill | K39: Online Pharmacy
A40: Drug E | B40: Company Z | C40: Tablet | D40: 250 mg | E40: 50 g | F40: 1351 | G40: 41781 | H40: 45201 | I40: Asia | J40: Stephanie Collins | K40: Clinics
...

Sheet Cleaned_Data
A1: Drug Name | B1: Manufacturer | C1: Dosage Form | D1: Strength | E1: Package Size | F1: Units Sold | G1: Revenue | H1: Sale Date | I1: Region | J1: Sales Representative | K1: Customer Type | L1: Month | M1: Quarter | N1: Revenue Category | O1: Target Multiplier | P1: Target Revenue | Q1: Achievment % | R1: Performance Status
A2: Drug B | B2: Company W | C2: Tablet | D2: 100 mg/ml | E2: 50 g | F2: 1500 | G2: 43833 | H2: 45329 | I2: South America | J2: Susan Hernandez | K2: Clinics | L2: =TEXT(H2,"MMM") -> Feb | M2: ="Q"&ROUNDUP(MONTH(H2)/3,0) -> Q1 | N2: =IF(G2>40000,"High", IF(G2>20000,"Medium","Low")) -> High | O2: =_xlfn.XLOOKUP(I2,Helper_Table!A:A,Helper_Table!B:B) -> 1.1 | P2: =G2*O2 -> 48216.3 | Q2: =G2/P2 -> 0.90909091 | R2: =IF(Q2>=1,"Achieved","Below Target") -> Below Target
A3: Drug B | B3: Company X | C3: Cream | D3: 500 mg | E3: 100 ml | F3: 1194 | G3: 48717 | H3: 45146 | I3: South America | J3: Jackie Wagner | K3: Clinics | L3: =TEXT(H3,"MMM") -> Aug | M3: ="Q"&ROUNDUP(MONTH(H3)/3,0) -> Q3 | N3: =IF(G3>40000,"High", IF(G3>20000,"Medium","Low")) -> High | O3: =_xlfn.XLOOKUP(I3,Helper_Table!A:A,Helper_Table!B:B) -> 1.1 | P3: =G3*O3 -> 53588.7 | Q3: =G3/P3 -> 0.90909091 | R3: =IF(Q3>=1,"Achieved","Below Target") -> Below Target
A4: Drug E | B4: Company X | C4: Capsule | D4: 50 mg | E4: 60 | F4: 618 | G4: 8744 | H4: 45458 | I4: Africa | J4: Mariah Mccoy | K4: Hospitals | L4: =TEXT(H4,"MMM") -> Jun | M4: ="Q"&ROUNDUP(MONTH(H4)/3,0) -> Q2 | N4: =IF(G4>40000,"High", IF(G4>20000,"Medium","Low")) -> Low | O4: =_xlfn.XLOOKUP(I4,Helper_Table!A:A,Helper_Table!B:B) -> 0.9 | P4: =G4*O4 -> 7869.6 | Q4: =G4/P4 -> 1.1111111 | R4: =IF(Q4>=1,"Achieved","Below Target") -> Achieved
A5: Drug E | B5: Company X | C5: Injection | D5: 10 mg | E5: 100 ml | F5: 1455 | G5: 25321 | H5: 45488 | I5: Asia | J5: Courtney Doyle | K5: Pharmacy | L5: =TEXT(H5,"MMM") -> Jul | M5: ="Q"&ROUNDUP(MONTH(H5)/3,0) -> Q3 | N5: =IF(G5>40000,"High", IF(G5>20000,"Medium","Low")) -> Medium | O5: =_xlfn.XLOOKUP(I5,Helper_Table!A:A,Helper_Table!B:B) -> 0.95 | P5: =G5*O5 -> 24054.95 | Q5: =G5/P5 -> 1.0526316 | R5: =IF(Q5>=1,"Achieved","Below Target") -> Achieved
A6: Drug C | B6: Company V | C6: Tablet | D6: 100 mg/ml | E6: 50 g | F6: 130 | G6: 13669 | H6: 45151 | I6: South America | J6: Dawn Torres | K6: Clinics | L6: =TEXT(H6,"MMM") -> Aug | M6: ="Q"&ROUNDUP(MONTH(H6)/3,0) -> Q3 | N6: =IF(G6>40000,"High", IF(G6>20000,"Medium","Low")) -> Low | O6: =_xlfn.XLOOKUP(I6,Helper_Table!A:A,Helper_Table!B:B) -> 1.1 | P6: =G6*O6 -> 15035.9 | Q6: =G6/P6 -> 0.90909091 | R6: =IF(Q6>=1,"Achieved","Below Target") -> Below Target
A7: Drug B | B7: Company V | C7: Capsule | D7: 100 mg/ml | E7: 10 ml | F7: 619 | G7: 7552 | H7: 45265 | I7: Europe | J7: Jessica Faulkner | K7: Hospitals | L7: =TEXT(H7,"MMM") -> Dec | M7: ="Q"&ROUNDUP(MONTH(H7)/3,0) -> Q4 | N7: =IF(G7>40000,"High", IF(G7>20000,"Medium","Low")) -> Low | O7: =_xlfn.XLOOKUP(I7,Helper_Table!A:A,Helper_Table!B:B) -> 1.1 | P7: =G7*O7 -> 8307.2 | Q7: =G7/P7 -> 0.90909091 | R7: =IF(Q7>=1,"Achieved","Below Target") -> Below Target
A8: Drug C | B8: Company X | C8: Cream | D8: 500 mg | E8: 30 | F8: 1779 | G8: 48563 | H8: 45146 | I8: North America | J8: Alicia Howard | K8: Hospitals | L8: =TEXT(H8,"MMM") -> Aug | M8: ="Q"&ROUNDUP(MONTH(H8)/3,0) -> Q3 | N8: =IF(G8>40000,"High", IF(G8>20000,"Medium","Low")) -> High | O8: =_xlfn.XLOOKUP(I8,Helper_Table!A:A,Helper_Table!B:B) -> 1.2 | P8: =G8*O8 -> 58275.6 | Q8: =G8/P8 -> 0.83333333 | R8: =IF(Q8>=1,"Achieved","Below Target") -> Below Target
A9: Drug B | B9: Company X | C9: Tablet | D9: 500 mg | E9: 10 ml | F9: 1727 | G9: 13672 | H9: 45290 | I9: Asia | J9: David Hill | K9: Online Pharmacy | L9: =TEXT(H9,"MMM") -> Dec | M9: ="Q"&ROUNDUP(MONTH(H9)/3,0) -> Q4 | N9: =IF(G9>40000,"High", IF(G9>20000,"Medium","Low")) -> Low | O9: =_xlfn.XLOOKUP(I9,Helper_Table!A:A,Helper_Table!B:B) -> 0.95 | P9: =G9*O9 -> 12988.4 | Q9: =G9/P9 -> 1.0526316 | R9: =IF(Q9>=1,"Achieved","Below Target") -> Achieved
A10: Drug A | B10: Company V | C10: Capsule | D10: 500 mg | E10: 50 g | F10: 451 | G10: 45835 | H10: 45244 | I10: Asia | J10: Matthew Johnson | K10: Supermarkets | L10: =TEXT(H10,"MMM") -> Nov | M10: ="Q"&ROUNDUP(MONTH(H10)/3,0) -> Q4 | N10: =IF(G10>40000,"High", IF(G10>20000,"Medium","Low")) -> High | O10: =_xlfn.XLOOKUP(I10,Helper_Table!A:A,Helper_Table!B:B) -> 0.95 | P10: =G10*O10 -> 43543.25 | Q10: =G10/P10 -> 1.0526316 | R10: =IF(Q10>=1,"Achieved","Below Target") -> Achieved
A11: Drug C | B11: Company X | C11: Cream | D11: 10 mg | E11: 10 ml | F11: 1006 | G11: 31716 | H11: 45435 | I11: Asia | J11: Kimberly Murphy | K11: Supermarkets | L11: =TEXT(H11,"MMM") -> May | M11: ="Q"&ROUNDUP(MONTH(H11)/3,0) -> Q2 | N11: =IF(G11>40000,"High", IF(G11>20000,"Medium","Low")) -> Medium | O11: =_xlfn.XLOOKUP(I11,Helper_Table!A:A,Helper_Table!B:B) -> 0.95 | P11: =G11*O11 -> 30130.2 | Q11: =G11/P11 -> 1.0526316 | R11: =IF(Q11>=1,"Achieved","Below Target") -> Achieved
A12: Drug C | B12: Company Y | C12: Capsule | D12: 50 mg | E12: 100 ml | F12: 1633 | G12: 33931 | H12: 45430 | I12: Europe | J12: Tyler Brown | K12: Pharmacy | L12: =TEXT(H12,"MMM") -> May | M12: ="Q"&ROUNDUP(MONTH(H12)/3,0) -> Q2 | N12: =IF(G12>40000,"High", IF(G12>20000,"Medium","Low")) -> Medium | O12: =_xlfn.XLOOKUP(I12,Helper_Table!A:A,Helper_Table!B:B) -> 1.1 | P12: =G12*O12 -> 37324.1 | Q12: =G12/P12 -> 0.90909091 | R12: =IF(Q12>=1,"Achieved","Below Target") -> Below Target
A13: Drug A | B13: Company Z | C13: Cream | D13: 50 mg | E13: 30 | F13: 128 | G13: 35258 | H13: 45238 | I13: North America | J13: Sheila Coleman | K13: Online Pharmacy | L13: =TEXT(H13,"MMM") -> Nov | M13: ="Q"&ROUNDUP(MONTH(H13)/3,0) -> Q4 | N13: =IF(G13>40000,"High", IF(G13>20000,"Medium","Low")) -> Medium | O13: =_xlfn.XLOOKUP(I13,Helper_Table!A:A,Helper_Table!B:B) -> 1.2 | P13: =G13*O13 -> 42309.6 | Q13: =G13/P13 -> 0.83333333 | R13: =IF(Q13>=1,"Achieved","Below Target") -> Below Target
A14: Drug C | B14: Company V | C14: Injection | D14: 500 mg | E14: 10 ml | F14: 504 | G14: 36459 | H14: 45157 | I14: Europe | J14: Douglas Rodriguez | K14: Pharmacy | L14: =TEXT(H14,"MMM") -> Aug | M14: ="Q"&ROUNDUP(MONTH(H14)/3,0) -> Q3 | N14: =IF(G14>40000,"High", IF(G14>20000,"Medium","Low")) -> Medium | O14: =_xlfn.XLOOKUP(I14,Helper_Table!A:A,Helper_Table!B:B) -> 1.1 | P14: =G14*O14 -> 40104.9 | Q14: =G14/P14 -> 0.90909091 | R14: =IF(Q14>=1,"Achieved","Below Target") -> Below Target
A15: Drug E | B15: Company V | C15: Cream | D15: 500 mg | E15: 100 ml | F15: 216 | G15: 32152 | H15: 45481 | I15: Europe | J15: Brandi King | K15: Pharmacy | L15: =TEXT(H15,"MMM") -> Jul | M15: ="Q"&ROUNDUP(MONTH(H15)/3,0) -> Q3 | N15: =IF(G15>40000,"High", IF(G15>20000,"Medium","Low")) -> Medium | O15: =_xlfn.XLOOKUP(I15,Helper_Table!A:A,Helper_Table!B:B) -> 1.1 | P15: =G15*O15 -> 35367.2 | Q15: =G15/P15 -> 0.90909091 | R15: =IF(Q15>=1,"Achieved","Below Target") -> Below Target
A16: Drug E | B16: Company V | C16: Injection | D16: 10 mg | E16: 10 ml | F16: 1986 | G16: 13538 | H16: 45263 | I16: Europe | J16: Susan Brewer | K16: Pharmacy | L16: =TEXT(H16,"MMM") -> Dec | M16: ="Q"&ROUNDUP(MONTH(H16)/3,0) -> Q4 | N16: =IF(G16>40000,"High", IF(G16>20000,"Medium","Low")) -> Low | O16: =_xlfn.XLOOKUP(I16,Helper_Table!A:A,Helper_Table!B:B) -> 1.1 | P16: =G16*O16 -> 14891.8 | Q16: =G16/P16 -> 0.90909091 | R16: =IF(Q16>=1,"Achieved","Below Target") -> Below Target
A17: Drug A | B17: Company W | C17: Cream | D17: 50 mg | E17: 30 | F17: 1977 | G17: 9566 | H17: 45486 | I17: Africa | J17: Latoya Wright | K17: Online Pharmacy | L17: =TEXT(H17,"MMM") -> Jul | M17: ="Q"&ROUNDUP(MONTH(H17)/3,0) -> Q3 | N17: =IF(G17>40000,"High", IF(G17>20000,"Medium","Low")) -> Low | O17: =_xlfn.XLOOKUP(I17,Helper_Table!A:A,Helper_Table!B:B) -> 0.9 | P17: =G17*O17 -> 8609.4 | Q17: =G17/P17 -> 1.1111111 | R17: =IF(Q17>=1,"Achieved","Below Target") -> Achieved
A18: Drug A | B18: Company V | C18: Tablet | D18: 100 mg/ml | E18: 50 g | F18: 1320 | G18: 29932 | H18: 45160 | I18: North America | J18: Richard Edwards | K18: Clinics | L18: =TEXT(H18,"MMM") -> Aug | M18: ="Q"&ROUNDUP(MONTH(H18)/3,0) -> Q3 | N18: =IF(G18>40000,"High", IF(G18>20000,"Medium","Low")) -> Medium | O18: =_xlfn.XLOOKUP(I18,Helper_Table!A:A,Helper_Table!B:B) -> 1.2 | P18: =G18*O18 -> 35918.4 | Q18: =G18/P18 -> 0.83333333 | R18: =IF(Q18>=1,"Achieved","Below Target") -> Below Target
A19: Drug E | B19: Company W | C19: Cream | D19: 10 mg | E19: 30 | F19: 1766 | G19: 45608 | H19: 45349 | I19: South America | J19: Mr. Michael Taylor | K19: Pharmacy | L19: =TEXT(H19,"MMM") -> Feb | M19: ="Q"&ROUNDUP(MONTH(H19)/3,0) -> Q1 | N19: =IF(G19>40000,"High", IF(G19>20000,"Medium","Low")) -> High | O19: =_xlfn.XLOOKUP(I19,Helper_Table!A:A,Helper_Table!B:B) -> 1.1 | P19: =G19*O19 -> 50168.8 | Q19: =G19/P19 -> 0.90909091 | R19: =IF(Q19>=1,"Achieved","Below Target") -> Below Target
A20: Drug B | B20: Company X | C20: Syrup | D20: 100 mg/ml | E20: 60 | F20: 1078 | G20: 42394 | H20: 45303 | I20: South America | J20: Angela Castro | K20: Online Pharmacy | L20: =TEXT(H20,"MMM") -> Jan | M20: ="Q"&ROUNDUP(MONTH(H20)/3,0) -> Q1 | N20: =IF(G20>40000,"High", IF(G20>20000,"Medium","Low")) -> High | O20: =_xlfn.XLOOKUP(I20,Helper_Table!A:A,Helper_Table!B:B) -> 1.1 | P20: =G20*O20 -> 46633.4 | Q20: =G20/P20 -> 0.90909091 | R20: =IF(Q20>=1,"Achieved","Below Target") -> Below Target
A21: Drug C | B21: Company X | C21: Injection | D21: 500 mg | E21: 60 | F21: 783 | G21: 48016 | H21: 45315 | I21: Asia | J21: Christie Brown | K21: Clinics | L21: =TEXT(H21,"MMM") -> Jan | M21: ="Q"&ROUNDUP(MONTH(H21)/3,0) -> Q1 | N21: =IF(G21>40000,"High", IF(G21>20000,"Medium","Low")) -> High | O21: =_xlfn.XLOOKUP(I21,Helper_Table!A:A,Helper_Table!B:B) -> 0.95 | P21: =G21*O21 -> 45615.2 | Q21: =G21/P21 -> 1.0526316 | R21: =IF(Q21>=1,"Achieved","Below Target") -> Achieved
A22: Drug E | B22: Company X | C22: Capsule | D22: 100 mg/ml | E22: 60 | F22: 1161 | G22: 11048 | H22: 45299 | I22: Europe | J22: Annette Fisher | K22: Clinics | L22: =TEXT(H22,"MMM") -> Jan | M22: ="Q"&ROUNDUP(MONTH(H22)/3,0) -> Q1 | N22: =IF(G22>40000,"High", IF(G22>20000,"Medium","Low")) -> Low | O22: =_xlfn.XLOOKUP(I22,Helper_Table!A:A,Helper_Table!B:B) -> 1.1 | P22: =G22*O22 -> 12152.8 | Q22: =G22/P22 -> 0.90909091 | R22: =IF(Q22>=1,"Achieved","Below Target") -> Below Target
A23: Drug A | B23: Company X | C23: Capsule | D23: 50 mg | E23: 50 g | F23: 1820 | G23: 16952 | H23: 45366 | I23: Africa | J23: Katelyn Smith | K23: Hospitals | L23: =TEXT(H23,"MMM") -> Mar | M23: ="Q"&ROUNDUP(MONTH(H23)/3,0) -> Q1 | N23: =IF(G23>40000,"High", IF(G23>20000,"Medium","Low")) -> Low | O23: =_xlfn.XLOOKUP(I23,Helper_Table!A:A,Helper_Table!B:B) -> 0.9 | P23: =G23*O23 -> 15256.8 | Q23: =G23/P23 -> 1.1111111 | R23: =IF(Q23>=1,"Achieved","Below Target") -> Achieved
A24: Drug D | B24: Company V | C24: Tablet | D24: 50 mg | E24: 60 | F24: 147 | G24: 28543 | H24: 45437 | I24: Africa | J24: Crystal Lawrence | K24: Hospitals | L24: =TEXT(H24,"MMM") -> May | M24: ="Q"&ROUNDUP(MONTH(H24)/3,0) -> Q2 | N24: =IF(G24>40000,"High", IF(G24>20000,"Medium","Low")) -> Medium | O24: =_xlfn.XLOOKUP(I24,Helper_Table!A:A,Helper_Table!B:B) -> 0.9 | P24: =G24*O24 -> 25688.7 | Q24: =G24/P24 -> 1.1111111 | R24: =IF(Q24>=1,"Achieved","Below Target") -> Achieved
A25: Drug B | B25: Company Z | C25: Capsule | D25: 250 mg | E25: 60 | F25: 990 | G25: 5766 | H25: 45172 | I25: North America | J25: Katherine Sexton | K25: Online Pharmacy | L25: =TEXT(H25,"MMM") -> Sep | M25: ="Q"&ROUNDUP(MONTH(H25)/3,0) -> Q3 | N25: =IF(G25>40000,"High", IF(G25>20000,"Medium","Low")) -> Low | O25: =_xlfn.XLOOKUP(I25,Helper_Table!A:A,Helper_Table!B:B) -> 1.2 | P25: =G25*O25 -> 6919.2 | Q25: =G25/P25 -> 0.83333333 | R25: =IF(Q25>=1,"Achieved","Below Target") -> Below Target
A26: Drug B | B26: Company Z | C26: Injection | D26: 500 mg | E26: 60 | F26: 223 | G26: 23153 | H26: 45371 | I26: Asia | J26: Felicia Jones | K26: Online Pharmacy | L26: =TEXT(H26,"MMM") -> Mar | M26: ="Q"&ROUNDUP(MONTH(H26)/3,0) -> Q1 | N26: =IF(G26>40000,"High", IF(G26>20000,"Medium","Low")) -> Medium | O26: =_xlfn.XLOOKUP(I26,Helper_Table!A:A,Helper_Table!B:B) -> 0.95 | P26: =G26*O26 -> 21995.35 | Q26: =G26/P26 -> 1.0526316 | R26: =IF(Q26>=1,"Achieved","Below Target") -> Achieved
A27: Drug D | B27: Company Z | C27: Syrup | D27: 250 mg | E27: 50 g | F27: 855 | G27: 22920 | H27: 45313 | I27: South America | J27: Lisa Johnson | K27: Supermarkets | L27: =TEXT(H27,"MMM") -> Jan | M27: ="Q"&ROUNDUP(MONTH(H27)/3,0) -> Q1 | N27: =IF(G27>40000,"High", IF(G27>20000,"Medium","Low")) -> Medium | O27: =_xlfn.XLOOKUP(I27,Helper_Table!A:A,Helper_Table!B:B) -> 1.1 | P27: =G27*O27 -> 25212 | Q27: =G27/P27 -> 0.90909091 | R27: =IF(Q27>=1,"Achieved","Below Target") -> Below Target
A28: Drug C | B28: Company X | C28: Cream | D28: 50 mg | E28: 100 ml | F28: 968 | G28: 6595 | H28: 45264 | I28: Africa | J28: Amber Hill | K28: Hospitals | L28: =TEXT(H28,"MMM") -> Dec | M28: ="Q"&ROUNDUP(MONTH(H28)/3,0) -> Q4 | N28: =IF(G28>40000,"High", IF(G28>20000,"Medium","Low")) -> Low | O28: =_xlfn.XLOOKUP(I28,Helper_Table!A:A,Helper_Table!B:B) -> 0.9 | P28: =G28*O28 -> 5935.5 | Q28: =G28/P28 -> 1.1111111 | R28: =IF(Q28>=1,"Achieved","Below Target") -> Achieved
A29: Drug B | B29: Company W | C29: Cream | D29: 10 mg | E29: 10 ml | F29: 1378 | G29: 37523 | H29: 45271 | I29: South America | J29: Rebecca Lawrence | K29: Online Pharmacy | L29: =TEXT(H29,"MMM") -> Dec | M29: ="Q"&ROUNDUP(MONTH(H29)/3,0) -> Q4 | N29: =IF(G29>40000,"High", IF(G29>20000,"Medium","Low")) -> Medium | O29: =_xlfn.XLOOKUP(I29,Helper_Table!A:A,Helper_Table!B:B) -> 1.1 | P29: =G29*O29 -> 41275.3 | Q29: =G29/P29 -> 0.90909091 | R29: =IF(Q29>=1,"Achieved","Below Target") -> Below Target
A30: Drug B | B30: Company Z | C30: Tablet | D30: 500 mg | E30: 100 ml | F30: 1473 | G30: 23815 | H30: 45495 | I30: South America | J30: John Smith | K30: Supermarkets | L30: =TEXT(H30,"MMM") -> Jul | M30: ="Q"&ROUNDUP(MONTH(H30)/3,0) -> Q3 | N30: =IF(G30>40000,"High", IF(G30>20000,"Medium","Low")) -> Medium | O30: =_xlfn.XLOOKUP(I30,Helper_Table!A:A,Helper_Table!B:B) -> 1.1 | P30: =G30*O30 -> 26196.5 | Q30: =G30/P30 -> 0.90909091 | R30: =IF(Q30>=1,"Achieved","Below Target") -> Below Target
A31: Drug C | B31: Company X | C31: Capsule | D31: 250 mg | E31: 100 ml | F31: 791 | G31: 40754 | H31: 45417 | I31: Africa | J31: Scott Jones | K31: Hospitals | L31: =TEXT(H31,"MMM") -> May | M31: ="Q"&ROUNDUP(MONTH(H31)/3,0) -> Q2 | N31: =IF(G31>40000,"High", IF(G31>20000,"Medium","Low")) -> High | O31: =_xlfn.XLOOKUP(I31,Helper_Table!A:A,Helper_Table!B:B) -> 0.9 | P31: =G31*O31 -> 36678.6 | Q31: =G31/P31 -> 1.1111111 | R31: =IF(Q31>=1,"Achieved","Below Target") -> Achieved
A32: Drug C | B32: Company V | C32: Tablet | D32: 10 mg | E32: 50 g | F32: 1523 | G32: 35645 | H32: 45211 | I32: South America | J32: Cynthia Cook | K32: Clinics | L32: =TEXT(H32,"MMM") -> Oct | M32: ="Q"&ROUNDUP(MONTH(H32)/3,0) -> Q4 | N32: =IF(G32>40000,"High", IF(G32>20000,"Medium","Low")) -> Medium | O32: =_xlfn.XLOOKUP(I32,Helper_Table!A:A,Helper_Table!B:B) -> 1.1 | P32: =G32*O32 -> 39209.5 | Q32: =G32/P32 -> 0.90909091 | R32: =IF(Q32>=1,"Achieved","Below Target") -> Below Target
A33: Drug E | B33: Company W | C33: Cream | D33: 250 mg | E33: 50 g | F33: 1214 | G33: 1820 | H33: 45359 | I33: South America | J33: Randy Dunn | K33: Online Pharmacy | L33: =TEXT(H33,"MMM") -> Mar | M33: ="Q"&ROUNDUP(MONTH(H33)/3,0) -> Q1 | N33: =IF(G33>40000,"High", IF(G33>20000,"Medium","Low")) -> Low | O33: =_xlfn.XLOOKUP(I33,Helper_Table!A:A,Helper_Table!B:B) -> 1.1 | P33: =G33*O33 -> 2002 | Q33: =G33/P33 -> 0.90909091 | R33: =IF(Q33>=1,"Achieved","Below Target") -> Below Target
A34: Drug C | B34: Company V | C34: Injection | D34: 250 mg | E34: 60 | F34: 440 | G34: 13578 | H34: 45470 | I34: Asia | J34: Michael Cisneros | K34: Hospitals | L34: =TEXT(H34,"MMM") -> Jun | M34: ="Q"&ROUNDUP(MONTH(H34)/3,0) -> Q2 | N34: =IF(G34>40000,"High", IF(G34>20000,"Medium","Low")) -> Low | O34: =_xlfn.XLOOKUP(I34,Helper_Table!A:A,Helper_Table!B:B) -> 0.95 | P34: =G34*O34 -> 12899.1 | Q34: =G34/P34 -> 1.0526316 | R34: =IF(Q34>=1,"Achieved","Below Target") -> Achieved
A35: Drug D | B35: Company Y | C35: Syrup | D35: 10 mg | E35: 60 | F35: 1574 | G35: 47682 | H35: 45396 | I35: Africa | J35: Crystal Keller | K35: Supermarkets | L35: =TEXT(H35,"MMM") -> Apr | M35: ="Q"&ROUNDUP(MONTH(H35)/3,0) -> Q2 | N35: =IF(G35>40000,"High", IF(G35>20000,"Medium","Low")) -> High | O35: =_xlfn.XLOOKUP(I35,Helper_Table!A:A,Helper_Table!B:B) -> 0.9 | P35: =G35*O35 -> 42913.8 | Q35: =G35/P35 -> 1.1111111 | R35: =IF(Q35>=1,"Achieved","Below Target") -> Achieved
A36: Drug A | B36: Company W | C36: Cream | D36: 250 mg | E36: 50 g | F36: 1880 | G36: 41604 | H36: 45295 | I36: North America | J36: Christina Lopez | K36: Pharmacy | L36: =TEXT(H36,"MMM") -> Jan | M36: ="Q"&ROUNDUP(MONTH(H36)/3,0) -> Q1 | N36: =IF(G36>40000,"High", IF(G36>20000,"Medium","Low")) -> High | O36: =_xlfn.XLOOKUP(I36,Helper_Table!A:A,Helper_Table!B:B) -> 1.2 | P36: =G36*O36 -> 49924.8 | Q36: =G36/P36 -> 0.83333333 | R36: =IF(Q36>=1,"Achieved","Below Target") -> Below Target
A37: Drug E | B37: Company Z | C37: Tablet | D37: 100 mg/ml | E37: 10 ml | F37: 383 | G37: 21024 | H37: 45298 | I37: South America | J37: Christopher Taylor | K37: Hospitals | L37: =TEXT(H37,"MMM") -> Jan | M37: ="Q"&ROUNDUP(MONTH(H37)/3,0) -> Q1 | N37: =IF(G37>40000,"High", IF(G37>20000,"Medium","Low")) -> Medium | O37: =_xlfn.XLOOKUP(I37,Helper_Table!A:A,Helper_Table!B:B) -> 1.1 | P37: =G37*O37 -> 23126.4 | Q37: =G37/P37 -> 0.90909091 | R37: =IF(Q37>=1,"Achieved","Below Target") -> Below Target
A38: Drug E | B38: Company Y | C38: Injection | D38: 10 mg | E38: 10 ml | F38: 253 | G38: 18363 | H38: 45459 | I38: South America | J38: Lisa Alvarado | K38: Online Pharmacy | L38: =TEXT(H38,"MMM") -> Jun | M38: ="Q"&ROUNDUP(MONTH(H38)/3,0) -> Q2 | N38: =IF(G38>40000,"High", IF(G38>20000,"Medium","Low")) -> Low | O38: =_xlfn.XLOOKUP(I38,Helper_Table!A:A,Helper_Table!B:B) -> 1.1 | P38: =G38*O38 -> 20199.3 | Q38: =G38/P38 -> 0.90909091 | R38: =IF(Q38>=1,"Achieved","Below Target") -> Below Target
A39: Drug C | B39: Company Y | C39: Syrup | D39: 100 mg/ml | E39: 30 | F39: 1818 | G39: 2347 | H39: 45320 | I39: Africa | J39: Kerry Oneill | K39: Online Pharmacy | L39: =TEXT(H39,"MMM") -> Jan | M39: ="Q"&ROUNDUP(MONTH(H39)/3,0) -> Q1 | N39: =IF(G39>40000,"High", IF(G39>20000,"Medium","Low")) -> Low | O39: =_xlfn.XLOOKUP(I39,Helper_Table!A:A,Helper_Table!B:B) -> 0.9 | P39: =G39*O39 -> 2112.3 | Q39: =G39/P39 -> 1.1111111 | R39: =IF(Q39>=1,"Achieved","Below Target") -> Achieved
A40: Drug E | B40: Company Z | C40: Tablet | D40: 250 mg | E40: 50 g | F40: 1351 | G40: 41781 | H40: 45201 | I40: Asia | J40: Stephanie Collins | K40: Clinics | L40: =TEXT(H40,"MMM") -> Oct | M40: ="Q"&ROUNDUP(MONTH(H40)/3,0) -> Q4 | N40: =IF(G40>40000,"High", IF(G40>20000,"Medium","Low")) -> High | O40: =_xlfn.XLOOKUP(I40,Helper_Table!A:A,Helper_Table!B:B) -> 0.95 | P40: =G40*O40 -> 39691.95 | Q40: =G40/P40 -> 1.0526316 | R40: =IF(Q40>=1,"Achieved","Below Target") -> Achieved
...

Sheet Helper_Table
A1: Region | B1: Target Multiplier
A2: Asia | B2: 0.95
A3: Europe | B3: 1.1
A4: Africa | B4: 0.9
A5: North America | B5: 1.2
A6: South America | B6: 1.1

Sheet Pivot_Tables
A1: Region | B1: Regional Revenue Value | E1: Month | F1: Monthly Revenue Value
A2: Africa | B2: 4627135 | E2: Jan | F2: 2230464 | H2: Sales Representative | I2: Sum of Revenue | J2: Sum of Units Sold
A3: Asia | B3: 4809529 | E3: Feb | F3: 1858322 | H3: Aaron Cline | I3: 15758 | J3: 1124
A4: Europe | B4: 5027740 | E4: Mar | F4: 2069146 | H4: Aaron Douglas | I4: 22379 | J4: 939
A5: North America | B5: 5367445 | E5: Apr | F5: 2176512 | H5: Aaron Miles | I5: 10654 | J5: 255
A6: South America | B6: 6246955 | E6: May | F6: 2348333 | H6: Adam Brown | I6: 16585 | J6: 1595
A7: Grand Total | B7: 26078804 | E7: Jun | F7: 1860874 | H7: Adam Cox | I7: 32469 | J7: 1245
E8: Jul | F8: 2192827 | H8: Adam Jones | I8: 42507 | J8: 1018
E9: Aug | F9: 2534352 | H9: Adam Shelton | I9: 15055 | J9: 1530
E10: Sep | F10: 1821314 | H10: Alan Sloan | I10: 25507 | J10: 157
E11: Oct | F11: 2288096 | H11: Alejandro Bishop | I11: 4766 | J11: 1499
E12: Nov | F12: 2449237 | H12: Alexander Maynard | I12: 30615 | J12: 1509
E13: Dec | F13: 2249327 | H13: Alexander Moore | I13: 7812 | J13: 545
E14: Grand Total | F14: 26078804 | H14: Alexander Underwood | I14: 28088 | J14: 1544
A15: Drug Name | B15: Sum of Revenue | H15: Alexis Davis | I15: 44347 | J15: 908
A16: Drug B | B16: 5767109 | H16: Alexis Luna | I16: 2138 | J16: 1781
A17: Drug C | B17: 5259455 | H17: Alicia Castillo | I17: 44778 | J17: 132
A18: Drug A | B18: 5196471 | H18: Alicia Flynn | I18: 1411 | J18: 599
A19: Drug D | B19: 5092952 | H19: Alicia Howard | I19: 48563 | J19: 1779
A20: Drug E | B20: 4762817 | H20: Alicia Lambert | I20: 1303 | J20: 643
A21: Grand Total | B21: 26078804 | H21: Alisha Johnson | I21: 16495 | J21: 760
H22: Alison Santos DDS | I22: 38388 | J22: 743
A23: Customer Type | B23: Sum of Revenue | H23: Allen Cortez | I23: 37726 | J23: 676
A24: Clinics | B24: 5311106 | H24: Allison Alvarado | I24: 28440 | J24: 1461
A25: Hospitals | B25: 4965590 | H25: Allison Barker | I25: 19924 | J25: 1899
A26: Online Pharmacy | B26: 5203717 | H26: Allison Bennett | I26: 23935 | J26: 1882
A27: Pharmacy | B27: 6019543 | H27: Allison Duran | I27: 43749 | J27: 908
A28: Supermarkets | B28: 4578848 | H28: Alvin Rios | I28: 40553 | J28: 1289
A29: Grand Total | B29: 26078804 | H29: Alyssa Craig | I29: 25965 | J29: 347
H30: Alyssa Harvey | I30: 16796 | J30: 1937
H31: Amanda Adams | I31: 37982 | J31: 267
H32: Amanda Anderson | I32: 30188 | J32: 899
H33: Amanda Garcia | I33: 47317 | J33: 1228
H34: Amanda Underwood | I34: 2653 | J34: 1545
A35: Performance Status | B35: Sum of Revenue | H35: Amber Garcia | I35: 14269 | J35: 359
A36: Below Target | B36: 16642140 | H36: Amber Hill | I36: 6595 | J36: 968
A37: Achieved | B37: 9436664 | H37: Amy Adams | I37: 47220 | J37: 1372
A38: Grand Total | B38: 26078804 | H38: Amy Anderson | I38: 22584 | J38: 1621
H39: Amy Bentley | I39: 4193 | J39: 1902
H40: Amy Cruz | I40: 19837 | J40: 1875
...

Sheet Dashboard
A1: Pharmaceutical Sales & Commercial Analytics Dashboard
A7: Total Revenue💰 | E7: Total Units Sold📦 | I7: Average Achievement % | N7: Top Performing Region | T7: Top Selling Drug | Y7: Achievement Rate
A8: =ROUND(SUM(Cleaned_Data!G:G)/1000000,2)&"M" -> 26.08M | E8: =SUM(Cleaned_Data!F:F) -> 1056409 | I8: =AVERAGE(Cleaned_Data!Q:Q) -> 0.95830276 | N8: =_xlfn.XLOOKUP(MAX(Pivot_Tables!B1:B6),Pivot_Tables!B1:B6,Pivot_Tables!A1:A6) -> South America | T8: =_xlfn.XLOOKUP(MAX(Pivot_Tables!B15:B20),Pivot_Tables!B15:B20,Pivot_Tables!A15:A20) -> Drug B | Y8: =COUNTIF(Cleaned_Data!R:R,"Achieved")/COUNTA(Cleaned_Data!R:R) -> 0.37562438

Sheet Insights
